<?xml version="1.0" ?>
<robot name="robot_-3424064500001286933">
    <link name="anchor">
        <visual>
            <geometry>
                <anchor_module length="1.0"/>
            </geometry>
        </visual>
        <rotation lower_bound="0" upper_bound="180"/>
    </link>
    <link name="module_0">
        <visual>
            <geometry>
                <tilting_module length="0.9889023604622627"/>
            </geometry>
        </visual>
        <tilt lower_bound="0" upper_bound="90"/>
    </link>
    <joint name="module_0_joint" type="revolute">
        <parent link="anchor"/>
        <child link="module_0"/>
    </joint>
    <link name="module_1">
        <visual>
            <geometry>
                <tilting_module length="0.7621771844608689"/>
            </geometry>
        </visual>
        <tilt lower_bound="0" upper_bound="90"/>
    </link>
    <joint name="module_1_joint" type="revolute">
        <parent link="anchor"/>
        <child link="module_1"/>
    </joint>
    <link name="module_2">
        <visual>
            <geometry>
                <rotating_module length="2.1204497304575574"/>
            </geometry>
        </visual>
        <rotation lower_bound="0" upper_bound="180"/>
    </link>
    <joint name="module_2_joint" type="revolute">
        <parent link="module_1"/>
        <child link="module_2"/>
    </joint>
</robot>
