<?xml version="1.0" ?>
<robot name="robot_3144153331158528924">
    <link name="anchor">
        <visual>
            <geometry>
                <anchor_module length="1"/>
            </geometry>
        </visual>
        <rotation lower_bound="0" upper_bound="180"/>
    </link>
    <link name="module_0">
        <visual>
            <geometry>
                <tilting_module length="1.7172906073664027"/>
            </geometry>
        </visual>
        <tilt lower_bound="0" upper_bound="90"/>
    </link>
    <joint name="module_0_joint" type="revolute">
        <parent link="anchor"/>
        <child link="module_0"/>
    </joint>
    <link name="module_1">
        <visual>
            <geometry>
                <complex_module length="1.6655547414108949"/>
            </geometry>
        </visual>
        <tilt lower_bound="0" upper_bound="90"/>
        <rotation lower_bound="0" upper_bound="180"/>
    </link>
    <joint name="module_1_joint" type="revolute">
        <parent link="anchor"/>
        <child link="module_1"/>
    </joint>
    <link name="module_2">
        <visual>
            <geometry>
                <tilting_module length="1.1738322622144524"/>
            </geometry>
        </visual>
        <tilt lower_bound="0" upper_bound="90"/>
    </link>
    <joint name="module_2_joint" type="revolute">
        <parent link="module_1"/>
        <child link="module_2"/>
    </joint>
</robot>